<mujoco>
  <compiler angle="degree" coordinate="local" inertiafromgeom="true"/>
  <option integrator="RK4" timestep="0.02"/>
  <default>
    <joint armature="0" damping="0" limited="false"/>
    <geom conaffinity="0" condim="3" density="100" friction="1 0.5 0.5" margin="0" rgba="0.8 0.6 0.4 1"/>
  </default>
  <asset>
    <texture name="texplane" type="2d" builtin="flat" rgb1="0.95 0.95 0.95"  width="5120" height="5120"/>
    <material name="MatPlane" reflectance="0" texture="texplane" texrepeat="1 1" texuniform="true"  />
  </asset>
  <worldbody>
  <light directional="false" diffuse=".3 .3 .3" specular="0.3 0.3 0.3" pos="0 0 1000" />
  <camera name="top_view" mode="trackcom" pos="0 0 30" xyaxes="1 0 0 0 1 0" fovy = "45"/>

                
                <geom conaffinity="1" type="box" name="wall_0_0" size="2.5 2.5 1" pos="-10.0 -10.0 0.5" rgba="0.2 0.2 0.2 1" />
                
                <geom conaffinity="1" type="box" name="wall_0_1" size="2.5 2.5 1" pos="-10.0 -5.0 0.5" rgba="0.2 0.2 0.2 1" />
                
                <geom conaffinity="1" type="box" name="wall_0_2" size="2.5 2.5 1" pos="-10.0 0.0 0.5" rgba="0.2 0.2 0.2 1" />
                
                <geom conaffinity="1" type="box" name="wall_0_3" size="2.5 2.5 1" pos="-10.0 5.0 0.5" rgba="0.2 0.2 0.2 1" />
                
                <geom conaffinity="1" type="box" name="wall_0_4" size="2.5 2.5 1" pos="-10.0 10.0 0.5" rgba="0.2 0.2 0.2 1" />
                
                <geom conaffinity="1" type="box" name="wall_0_5" size="2.5 2.5 1" pos="-10.0 15.0 0.5" rgba="0.2 0.2 0.2 1" />
                
                <geom conaffinity="1" type="box" name="wall_0_6" size="2.5 2.5 1" pos="-10.0 20.0 0.5" rgba="0.2 0.2 0.2 1" />
                
                <geom conaffinity="1" type="box" name="wall_0_7" size="2.5 2.5 1" pos="-10.0 25.0 0.5" rgba="0.2 0.2 0.2 1" />
                
                <geom conaffinity="1" type="box" name="wall_0_8" size="2.5 2.5 1" pos="-10.0 30.0 0.5" rgba="0.2 0.2 0.2 1" />
                
                <geom conaffinity="1" type="box" name="wall_0_9" size="2.5 2.5 1" pos="-10.0 35.0 0.5" rgba="0.2 0.2 0.2 1" />
                
                <geom conaffinity="1" type="box" name="wall_0_10" size="2.5 2.5 1" pos="-10.0 40.0 0.5" rgba="0.2 0.2 0.2 1" />
                
                <geom conaffinity="1" type="box" name="wall_0_11" size="2.5 2.5 1" pos="-10.0 45.0 0.5" rgba="0.2 0.2 0.2 1" />
                
                <geom conaffinity="1" type="box" name="wall_0_12" size="2.5 2.5 1" pos="-10.0 50.0 0.5" rgba="0.2 0.2 0.2 1" />
                
                <geom conaffinity="1" type="box" name="wall_1_0" size="2.5 2.5 1" pos="-5.0 -10.0 0.5" rgba="0.2 0.2 0.2 1" />
                
                <geom conaffinity="1" type="box" name="wall_1_1" size="2.5 2.5 1" pos="-5.0 -5.0 0.5" rgba="0.2 0.2 0.2 1" />
                
                <geom conaffinity="1" type="box" name="wall_1_2" size="2.5 2.5 1" pos="-5.0 0.0 0.5" rgba="0.2 0.2 0.2 1" />
                
                <geom conaffinity="1" type="box" name="wall_1_3" size="2.5 2.5 1" pos="-5.0 5.0 0.5" rgba="0.2 0.2 0.2 1" />
                
                <geom conaffinity="1" type="box" name="wall_1_4" size="2.5 2.5 1" pos="-5.0 10.0 0.5" rgba="0.2 0.2 0.2 1" />
                
                <geom conaffinity="1" type="box" name="wall_1_5" size="2.5 2.5 1" pos="-5.0 15.0 0.5" rgba="0.2 0.2 0.2 1" />
                
                <geom conaffinity="1" type="box" name="wall_1_6" size="2.5 2.5 1" pos="-5.0 20.0 0.5" rgba="0.2 0.2 0.2 1" />
                
                <geom conaffinity="1" type="box" name="wall_1_7" size="2.5 2.5 1" pos="-5.0 25.0 0.5" rgba="0.2 0.2 0.2 1" />
                
                <geom conaffinity="1" type="box" name="wall_1_8" size="2.5 2.5 1" pos="-5.0 30.0 0.5" rgba="0.2 0.2 0.2 1" />
                
                <geom conaffinity="1" type="box" name="wall_1_9" size="2.5 2.5 1" pos="-5.0 35.0 0.5" rgba="0.2 0.2 0.2 1" />
                
                <geom conaffinity="1" type="box" name="wall_1_10" size="2.5 2.5 1" pos="-5.0 40.0 0.5" rgba="0.2 0.2 0.2 1" />
                
                <geom conaffinity="1" type="box" name="wall_1_11" size="2.5 2.5 1" pos="-5.0 45.0 0.5" rgba="0.2 0.2 0.2 1" />
                
                <geom conaffinity="1" type="box" name="wall_1_12" size="2.5 2.5 1" pos="-5.0 50.0 0.5" rgba="0.2 0.2 0.2 1" />
                
                <geom conaffinity="1" type="box" name="wall_2_0" size="2.5 2.5 1" pos="0.0 -10.0 0.5" rgba="0.2 0.2 0.2 1" />
                
                <geom conaffinity="1" type="box" name="wall_2_1" size="2.5 2.5 1" pos="0.0 -5.0 0.5" rgba="0.2 0.2 0.2 1" />
                
                <geom conaffinity="1" type="box" name="wall_2_3" size="2.5 2.5 1" pos="0.0 5.0 0.5" rgba="0.2 0.2 0.2 1" />
                
                <geom conaffinity="1" type="box" name="wall_2_9" size="2.5 2.5 1" pos="0.0 35.0 0.5" rgba="0.2 0.2 0.2 1" />
                
                <geom conaffinity="1" type="box" name="wall_2_11" size="2.5 2.5 1" pos="0.0 45.0 0.5" rgba="0.2 0.2 0.2 1" />
                
                <geom conaffinity="1" type="box" name="wall_2_12" size="2.5 2.5 1" pos="0.0 50.0 0.5" rgba="0.2 0.2 0.2 1" />
                
                <geom conaffinity="1" type="box" name="wall_3_0" size="2.5 2.5 1" pos="5.0 -10.0 0.5" rgba="0.2 0.2 0.2 1" />
                
                <geom conaffinity="1" type="box" name="wall_3_1" size="2.5 2.5 1" pos="5.0 -5.0 0.5" rgba="0.2 0.2 0.2 1" />
                
                <geom conaffinity="1" type="box" name="wall_3_3" size="2.5 2.5 1" pos="5.0 5.0 0.5" rgba="0.2 0.2 0.2 1" />
                
                <geom conaffinity="1" type="box" name="wall_3_5" size="2.5 2.5 1" pos="5.0 15.0 0.5" rgba="0.2 0.2 0.2 1" />
                
                <geom conaffinity="1" type="box" name="wall_3_7" size="2.5 2.5 1" pos="5.0 25.0 0.5" rgba="0.2 0.2 0.2 1" />
                
                <geom conaffinity="1" type="box" name="wall_3_8" size="2.5 2.5 1" pos="5.0 30.0 0.5" rgba="0.2 0.2 0.2 1" />
                
                <geom conaffinity="1" type="box" name="wall_3_9" size="2.5 2.5 1" pos="5.0 35.0 0.5" rgba="0.2 0.2 0.2 1" />
                
                <geom conaffinity="1" type="box" name="wall_3_11" size="2.5 2.5 1" pos="5.0 45.0 0.5" rgba="0.2 0.2 0.2 1" />
                
                <geom conaffinity="1" type="box" name="wall_3_12" size="2.5 2.5 1" pos="5.0 50.0 0.5" rgba="0.2 0.2 0.2 1" />
                
                <geom conaffinity="1" type="box" name="wall_4_0" size="2.5 2.5 1" pos="10.0 -10.0 0.5" rgba="0.2 0.2 0.2 1" />
                
                <geom conaffinity="1" type="box" name="wall_4_1" size="2.5 2.5 1" pos="10.0 -5.0 0.5" rgba="0.2 0.2 0.2 1" />
                
                <geom conaffinity="1" type="box" name="wall_4_3" size="2.5 2.5 1" pos="10.0 5.0 0.5" rgba="0.2 0.2 0.2 1" />
                
                <geom conaffinity="1" type="box" name="wall_4_5" size="2.5 2.5 1" pos="10.0 15.0 0.5" rgba="0.2 0.2 0.2 1" />
                
                <geom conaffinity="1" type="box" name="wall_4_7" size="2.5 2.5 1" pos="10.0 25.0 0.5" rgba="0.2 0.2 0.2 1" />
                
                <geom conaffinity="1" type="box" name="wall_4_11" size="2.5 2.5 1" pos="10.0 45.0 0.5" rgba="0.2 0.2 0.2 1" />
                
                <geom conaffinity="1" type="box" name="wall_4_12" size="2.5 2.5 1" pos="10.0 50.0 0.5" rgba="0.2 0.2 0.2 1" />
                
                <geom conaffinity="1" type="box" name="wall_5_0" size="2.5 2.5 1" pos="15.0 -10.0 0.5" rgba="0.2 0.2 0.2 1" />
                
                <geom conaffinity="1" type="box" name="wall_5_1" size="2.5 2.5 1" pos="15.0 -5.0 0.5" rgba="0.2 0.2 0.2 1" />
                
                <geom conaffinity="1" type="box" name="wall_5_3" size="2.5 2.5 1" pos="15.0 5.0 0.5" rgba="0.2 0.2 0.2 1" />
                
                <geom conaffinity="1" type="box" name="wall_5_4" size="2.5 2.5 1" pos="15.0 10.0 0.5" rgba="0.2 0.2 0.2 1" />
                
                <geom conaffinity="1" type="box" name="wall_5_5" size="2.5 2.5 1" pos="15.0 15.0 0.5" rgba="0.2 0.2 0.2 1" />
                
                <geom conaffinity="1" type="box" name="wall_5_7" size="2.5 2.5 1" pos="15.0 25.0 0.5" rgba="0.2 0.2 0.2 1" />
                
                <geom conaffinity="1" type="box" name="wall_5_8" size="2.5 2.5 1" pos="15.0 30.0 0.5" rgba="0.2 0.2 0.2 1" />
                
                <geom conaffinity="1" type="box" name="wall_5_9" size="2.5 2.5 1" pos="15.0 35.0 0.5" rgba="0.2 0.2 0.2 1" />
                
                <geom conaffinity="1" type="box" name="wall_5_11" size="2.5 2.5 1" pos="15.0 45.0 0.5" rgba="0.2 0.2 0.2 1" />
                
                <geom conaffinity="1" type="box" name="wall_5_12" size="2.5 2.5 1" pos="15.0 50.0 0.5" rgba="0.2 0.2 0.2 1" />
                
                <geom conaffinity="1" type="box" name="wall_6_0" size="2.5 2.5 1" pos="20.0 -10.0 0.5" rgba="0.2 0.2 0.2 1" />
                
                <geom conaffinity="1" type="box" name="wall_6_1" size="2.5 2.5 1" pos="20.0 -5.0 0.5" rgba="0.2 0.2 0.2 1" />
                
                <geom conaffinity="1" type="box" name="wall_6_11" size="2.5 2.5 1" pos="20.0 45.0 0.5" rgba="0.2 0.2 0.2 1" />
                
                <geom conaffinity="1" type="box" name="wall_6_12" size="2.5 2.5 1" pos="20.0 50.0 0.5" rgba="0.2 0.2 0.2 1" />
                
                <geom conaffinity="1" type="box" name="wall_7_0" size="2.5 2.5 1" pos="25.0 -10.0 0.5" rgba="0.2 0.2 0.2 1" />
                
                <geom conaffinity="1" type="box" name="wall_7_1" size="2.5 2.5 1" pos="25.0 -5.0 0.5" rgba="0.2 0.2 0.2 1" />
                
                <geom conaffinity="1" type="box" name="wall_7_3" size="2.5 2.5 1" pos="25.0 5.0 0.5" rgba="0.2 0.2 0.2 1" />
                
                <geom conaffinity="1" type="box" name="wall_7_4" size="2.5 2.5 1" pos="25.0 10.0 0.5" rgba="0.2 0.2 0.2 1" />
                
                <geom conaffinity="1" type="box" name="wall_7_5" size="2.5 2.5 1" pos="25.0 15.0 0.5" rgba="0.2 0.2 0.2 1" />
                
                <geom conaffinity="1" type="box" name="wall_7_7" size="2.5 2.5 1" pos="25.0 25.0 0.5" rgba="0.2 0.2 0.2 1" />
                
                <geom conaffinity="1" type="box" name="wall_7_8" size="2.5 2.5 1" pos="25.0 30.0 0.5" rgba="0.2 0.2 0.2 1" />
                
                <geom conaffinity="1" type="box" name="wall_7_9" size="2.5 2.5 1" pos="25.0 35.0 0.5" rgba="0.2 0.2 0.2 1" />
                
                <geom conaffinity="1" type="box" name="wall_7_10" size="2.5 2.5 1" pos="25.0 40.0 0.5" rgba="0.2 0.2 0.2 1" />
                
                <geom conaffinity="1" type="box" name="wall_7_11" size="2.5 2.5 1" pos="25.0 45.0 0.5" rgba="0.2 0.2 0.2 1" />
                
                <geom conaffinity="1" type="box" name="wall_7_12" size="2.5 2.5 1" pos="25.0 50.0 0.5" rgba="0.2 0.2 0.2 1" />
                
                <geom conaffinity="1" type="box" name="wall_8_0" size="2.5 2.5 1" pos="30.0 -10.0 0.5" rgba="0.2 0.2 0.2 1" />
                
                <geom conaffinity="1" type="box" name="wall_8_1" size="2.5 2.5 1" pos="30.0 -5.0 0.5" rgba="0.2 0.2 0.2 1" />
                
                <geom conaffinity="1" type="box" name="wall_8_5" size="2.5 2.5 1" pos="30.0 15.0 0.5" rgba="0.2 0.2 0.2 1" />
                
                <geom conaffinity="1" type="box" name="wall_8_9" size="2.5 2.5 1" pos="30.0 35.0 0.5" rgba="0.2 0.2 0.2 1" />
                
                <geom conaffinity="1" type="box" name="wall_8_11" size="2.5 2.5 1" pos="30.0 45.0 0.5" rgba="0.2 0.2 0.2 1" />
                
                <geom conaffinity="1" type="box" name="wall_8_12" size="2.5 2.5 1" pos="30.0 50.0 0.5" rgba="0.2 0.2 0.2 1" />
                
                <geom conaffinity="1" type="box" name="wall_9_0" size="2.5 2.5 1" pos="35.0 -10.0 0.5" rgba="0.2 0.2 0.2 1" />
                
                <geom conaffinity="1" type="box" name="wall_9_1" size="2.5 2.5 1" pos="35.0 -5.0 0.5" rgba="0.2 0.2 0.2 1" />
                
                <geom conaffinity="1" type="box" name="wall_9_3" size="2.5 2.5 1" pos="35.0 5.0 0.5" rgba="0.2 0.2 0.2 1" />
                
                <geom conaffinity="1" type="box" name="wall_9_4" size="2.5 2.5 1" pos="35.0 10.0 0.5" rgba="0.2 0.2 0.2 1" />
                
                <geom conaffinity="1" type="box" name="wall_9_5" size="2.5 2.5 1" pos="35.0 15.0 0.5" rgba="0.2 0.2 0.2 1" />
                
                <geom conaffinity="1" type="box" name="wall_9_7" size="2.5 2.5 1" pos="35.0 25.0 0.5" rgba="0.2 0.2 0.2 1" />
                
                <geom conaffinity="1" type="box" name="wall_9_8" size="2.5 2.5 1" pos="35.0 30.0 0.5" rgba="0.2 0.2 0.2 1" />
                
                <geom conaffinity="1" type="box" name="wall_9_9" size="2.5 2.5 1" pos="35.0 35.0 0.5" rgba="0.2 0.2 0.2 1" />
                
                <geom conaffinity="1" type="box" name="wall_9_11" size="2.5 2.5 1" pos="35.0 45.0 0.5" rgba="0.2 0.2 0.2 1" />
                
                <geom conaffinity="1" type="box" name="wall_9_12" size="2.5 2.5 1" pos="35.0 50.0 0.5" rgba="0.2 0.2 0.2 1" />
                
                <geom conaffinity="1" type="box" name="wall_10_0" size="2.5 2.5 1" pos="40.0 -10.0 0.5" rgba="0.2 0.2 0.2 1" />
                
                <geom conaffinity="1" type="box" name="wall_10_1" size="2.5 2.5 1" pos="40.0 -5.0 0.5" rgba="0.2 0.2 0.2 1" />
                
                <geom conaffinity="1" type="box" name="wall_10_3" size="2.5 2.5 1" pos="40.0 5.0 0.5" rgba="0.2 0.2 0.2 1" />
                
                <geom conaffinity="1" type="box" name="wall_10_11" size="2.5 2.5 1" pos="40.0 45.0 0.5" rgba="0.2 0.2 0.2 1" />
                
                <geom conaffinity="1" type="box" name="wall_10_12" size="2.5 2.5 1" pos="40.0 50.0 0.5" rgba="0.2 0.2 0.2 1" />
                
                <geom conaffinity="1" type="box" name="wall_11_0" size="2.5 2.5 1" pos="45.0 -10.0 0.5" rgba="0.2 0.2 0.2 1" />
                
                <geom conaffinity="1" type="box" name="wall_11_1" size="2.5 2.5 1" pos="45.0 -5.0 0.5" rgba="0.2 0.2 0.2 1" />
                
                <geom conaffinity="1" type="box" name="wall_11_2" size="2.5 2.5 1" pos="45.0 0.0 0.5" rgba="0.2 0.2 0.2 1" />
                
                <geom conaffinity="1" type="box" name="wall_11_3" size="2.5 2.5 1" pos="45.0 5.0 0.5" rgba="0.2 0.2 0.2 1" />
                
                <geom conaffinity="1" type="box" name="wall_11_4" size="2.5 2.5 1" pos="45.0 10.0 0.5" rgba="0.2 0.2 0.2 1" />
                
                <geom conaffinity="1" type="box" name="wall_11_5" size="2.5 2.5 1" pos="45.0 15.0 0.5" rgba="0.2 0.2 0.2 1" />
                
                <geom conaffinity="1" type="box" name="wall_11_6" size="2.5 2.5 1" pos="45.0 20.0 0.5" rgba="0.2 0.2 0.2 1" />
                
                <geom conaffinity="1" type="box" name="wall_11_7" size="2.5 2.5 1" pos="45.0 25.0 0.5" rgba="0.2 0.2 0.2 1" />
                
                <geom conaffinity="1" type="box" name="wall_11_8" size="2.5 2.5 1" pos="45.0 30.0 0.5" rgba="0.2 0.2 0.2 1" />
                
                <geom conaffinity="1" type="box" name="wall_11_9" size="2.5 2.5 1" pos="45.0 35.0 0.5" rgba="0.2 0.2 0.2 1" />
                
                <geom conaffinity="1" type="box" name="wall_11_10" size="2.5 2.5 1" pos="45.0 40.0 0.5" rgba="0.2 0.2 0.2 1" />
                
                <geom conaffinity="1" type="box" name="wall_11_11" size="2.5 2.5 1" pos="45.0 45.0 0.5" rgba="0.2 0.2 0.2 1" />
                
                <geom conaffinity="1" type="box" name="wall_11_12" size="2.5 2.5 1" pos="45.0 50.0 0.5" rgba="0.2 0.2 0.2 1" />
                
                <geom conaffinity="1" type="box" name="wall_12_0" size="2.5 2.5 1" pos="50.0 -10.0 0.5" rgba="0.2 0.2 0.2 1" />
                
                <geom conaffinity="1" type="box" name="wall_12_1" size="2.5 2.5 1" pos="50.0 -5.0 0.5" rgba="0.2 0.2 0.2 1" />
                
                <geom conaffinity="1" type="box" name="wall_12_2" size="2.5 2.5 1" pos="50.0 0.0 0.5" rgba="0.2 0.2 0.2 1" />
                
                <geom conaffinity="1" type="box" name="wall_12_3" size="2.5 2.5 1" pos="50.0 5.0 0.5" rgba="0.2 0.2 0.2 1" />
                
                <geom conaffinity="1" type="box" name="wall_12_4" size="2.5 2.5 1" pos="50.0 10.0 0.5" rgba="0.2 0.2 0.2 1" />
                
                <geom conaffinity="1" type="box" name="wall_12_5" size="2.5 2.5 1" pos="50.0 15.0 0.5" rgba="0.2 0.2 0.2 1" />
                
                <geom conaffinity="1" type="box" name="wall_12_6" size="2.5 2.5 1" pos="50.0 20.0 0.5" rgba="0.2 0.2 0.2 1" />
                
                <geom conaffinity="1" type="box" name="wall_12_7" size="2.5 2.5 1" pos="50.0 25.0 0.5" rgba="0.2 0.2 0.2 1" />
                
                <geom conaffinity="1" type="box" name="wall_12_8" size="2.5 2.5 1" pos="50.0 30.0 0.5" rgba="0.2 0.2 0.2 1" />
                
                <geom conaffinity="1" type="box" name="wall_12_9" size="2.5 2.5 1" pos="50.0 35.0 0.5" rgba="0.2 0.2 0.2 1" />
                
                <geom conaffinity="1" type="box" name="wall_12_10" size="2.5 2.5 1" pos="50.0 40.0 0.5" rgba="0.2 0.2 0.2 1" />
                
                <geom conaffinity="1" type="box" name="wall_12_11" size="2.5 2.5 1" pos="50.0 45.0 0.5" rgba="0.2 0.2 0.2 1" />
                
                <geom conaffinity="1" type="box" name="wall_12_12" size="2.5 2.5 1" pos="50.0 50.0 0.5" rgba="0.2 0.2 0.2 1" />
              
  <geom name="Goal" pos="0 0 0.25" size="0.5 0.5 0.5" type="box" rgba="1 0 0 1"/>
    <light cutoff="100" diffuse="1 1 1" dir="-0 0 -1.3" directional="true" exponent="1" pos="0 0 1.3" specular=".1 .1 .1"/>
    <geom conaffinity="1" condim="3" material="MatPlane" name="floor" pos="0 0 0" rgba="0.8 0.9 0.8 1" size="300 300 30" type="plane"/>
    <body name="torso" pos="0 0 0">
    
      <geom name="pointbody" pos="0 0 0.5" size="0.5" type="sphere"/>
      <geom name="pointarrow" pos="0.6 0 0.5" size="0.5 0.1 0.1" rgba="1 0 0 1" type="box"/>
      <joint axis="1 0 0" name="ballx" pos="0 0 0" type="slide"/>
      <joint axis="0 1 0" name="bally" pos="0 0 0" type="slide"/>
      <joint axis="0 0 1" limited="false" name="rot" pos="0 0 0" type="hinge"/>
    </body>
  </worldbody>
  <actuator>
    <!-- Those are just dummy actuators for providing ranges -->
    <motor ctrllimited="true" ctrlrange="-0.2 0.2" joint="ballx"/>
    <motor ctrllimited="true" ctrlrange="-0.2 0.2" joint="rot"/>
  </actuator>
</mujoco>
